<?xml version="1.0" ?>
<sdf version="1.10">
<model name="deliverer">
    <static>false</static>

    <link name="base_link">
        <pose>0 0 0 0 0 0</pose>
        <visual name="visual">
            <!--pose>0 0 15 0 0 0</pose-->
            <!--geometry><box><size>20 20 20</size></box></geometry-->
            <geometry><mesh><uri>file:///home/danil/Documents/ROSWorkspaces/RosMiniProject/src/making_delivery/models/rover.obj</uri></mesh></geometry>
            <material>
            <ambient>1 1 1 1</ambient>
            <diffuse>1 1 1 1</diffuse>
            <pbr><metal>
                <albedo_map>resources://T_Rover_BC_4K.png</albedo_map>
                <roughness>1</roughness>
                <metalness>0</metalness>
            </metal></pbr>
            </material>
        </visual>
        <collision name="collision">
            <pose>0 0 15 0 0 0</pose>
            <geometry><box><size>20 20 20</size></box></geometry>
        </collision>
    </link>

    <link name="left_front_wheel_link">
        <pose>10 10 5 1.57 0 0</pose>
        <visual name="visual">
            <pose>0 0 -1.1 0 0 0</pose>
            <geometry><box><size>5 5 5</size></box></geometry>
        </visual>
        <collision name="collision">
            <pose>0 0 -1.1 0 0 0</pose>
            <geometry><cylinder><radius>2.5</radius><length>2</length></cylinder></geometry>
        </collision>
        <inertial>
          <mass>50.0</mass>
          <inertia>
            <ixx>0.1</ixx>
            <iyy>0.1</iyy>
            <izz>0.1</izz>
          </inertia>
        </inertial>
    </link>
    <joint name="left_front_wheel_joint" type="revolute">
        <parent>base_link</parent>
        <child>left_front_wheel_link</child>
        <axis><xyz>0 0 1</xyz></axis>
    </joint>

    <link name="left_middle_wheel_link">
        <pose>0 10 5 1.57 0 0</pose>
        <visual name="visual">
            <pose>0 0 -1.1 0 0 0</pose>
            <geometry><cylinder><radius>2.5</radius><length>2</length></cylinder></geometry>
        </visual>
        <collision name="collision">
            <pose>0 0 -1.1 0 0 0</pose>
            <geometry><cylinder><radius>2.5</radius><length>2</length></cylinder></geometry>
        </collision>
    </link>
    <joint name="left_middle_wheel_joint" type="fixed">
        <parent>base_link</parent>
        <child>left_middle_wheel_link</child>
    </joint>

    <link name="left_back_wheel_link">
        <pose>-10 10 5 1.57 0 0</pose>
        <visual name="visual">
            <pose>0 0 -1.1 0 0 0</pose>
            <geometry><cylinder><radius>2.5</radius><length>2</length></cylinder></geometry>
        </visual>
        <collision name="collision">
            <pose>0 0 -1.1 0 0 0</pose>
            <geometry><cylinder><radius>2.5</radius><length>2</length></cylinder></geometry>
        </collision>
    </link>
    <joint name="left_back_wheel_joint" type="fixed">
        <parent>base_link</parent>
        <child>left_back_wheel_link</child>
    </joint>

    <link name="right_front_wheel_link">
        <pose>10 -10 5 1.57 0 0</pose>
        <visual name="visual">
            <pose>0 0 1.1 0 0 0</pose>
            <geometry><cylinder><radius>2.5</radius><length>2</length></cylinder></geometry>
        </visual>
        <collision name="collision">
            <pose>0 0 1.1 0 0 0</pose>
            <geometry><cylinder><radius>2.5</radius><length>2</length></cylinder></geometry>
        </collision>
    </link>
    <joint name="right_front_wheel_joint" type="fixed">
        <parent>base_link</parent>
        <child>right_front_wheel_link</child>
    </joint>

    <link name="right_middle_wheel_link">
        <pose>0 -10 5 1.57 0 0</pose>
        <visual name="visual">
            <pose>0 0 1.1 0 0 0</pose>
            <geometry><cylinder><radius>2.5</radius><length>2</length></cylinder></geometry>
        </visual>
        <collision name="collision">
            <pose>0 0 1.1 0 0 0</pose>
            <geometry><cylinder><radius>2.5</radius><length>2</length></cylinder></geometry>
        </collision>
    </link>
    <joint name="right_middle_wheel_joint" type="fixed">
        <parent>base_link</parent>
        <child>right_middle_wheel_link</child>
    </joint>

    <link name="right_back_wheel_link">
        <pose>-10 -10 5 1.57 0 0</pose>
        <visual name="visual">
            <pose>0 0 1.1 0 0 0</pose>
            <geometry><cylinder><radius>2.5</radius><length>2</length></cylinder></geometry>
        </visual>
        <collision name="collision">
            <pose>0 0 1.1 0 0 0</pose>
            <geometry><cylinder><radius>2.5</radius><length>2</length></cylinder></geometry>
        </collision>
    </link>
    <joint name="right_back_wheel_joint" type="fixed">
        <parent>base_link</parent>
        <child>right_back_wheel_link</child>
    </joint>
</model>
</sdf>
