<?xml version="1.0" ?>
<sdf version="1.10">
<model name="deliverer">
    <static>false</static>

    <link name="base_link">
        <pose>0 0 0 0 0 0</pose>
        <visual name="visual">
            <geometry><mesh><uri>file:///home/danil/Documents/ROSWorkspaces/RosMiniProject/src/making_delivery/models/rover.obj</uri></mesh></geometry>
            <material>
                <ambient>1 1 1 1</ambient>
                <diffuse>1 1 1 1</diffuse>
                <pbr><metal>
                    <albedo_map>resources://T_Rover_BC_4K.png</albedo_map>
                    <roughness>1</roughness>
                    <metalness>0</metalness>
                </metal></pbr>
            </material>
        </visual>
        <collision name="collision">
            <pose>0 0 8.92 0 0 0</pose>
            <geometry><box><size>24.6744 14.86332 17.8383</size></box></geometry>
        </collision>
    </link>
    <joint name="lid_joint" type="revolute">
        <parent>base_link</parent>
        <child>lid_link</child>
        <axis>
            <xyz>0 1 0</xyz>
            <limit><lower>0</lower><upper>1.29</upper></limit>
        </axis>
    </joint>
    <link name="lid_link">
        <pose>5.72194 0.139501 17.771 0 0 0</pose>
        <visual name="visual">
            <geometry><mesh><uri>file:///home/danil/Documents/ROSWorkspaces/RosMiniProject/src/making_delivery/models/lid.obj</uri></mesh></geometry>
            <material>
                <ambient>1 1 1 1</ambient>
                <diffuse>1 1 1 1</diffuse>
                <pbr><metal>
                    <albedo_map>resources://T_Lid_BC_4K.png</albedo_map>
                    <roughness>1</roughness>
                    <metalness>0</metalness>
                </metal></pbr>
            </material>
        </visual>
        <collision name="collision">
            <pose>-9.1069095 0 -0.5 0 0 0</pose>
            <geometry><box><size>18.213819 14.57102 1.619002</size></box></geometry>
        </collision>
    </link>

    <link name="flag_link">
        <pose>3.0149 -7.38887 14.4931 0 0 0</pose>
        <visual name="visual">
            <geometry><mesh><uri>file:///home/danil/Documents/ROSWorkspaces/RosMiniProject/src/making_delivery/models/flag.obj</uri></mesh></geometry>
            <material>
                <ambient>1 1 1 1</ambient>
                <diffuse>1 1 1 1</diffuse>
                <pbr><metal>
                    <albedo_map>resources://T_Flag_BC_4K.png</albedo_map>
                    <roughness>1</roughness>
                    <metalness>0</metalness>
                </metal></pbr>
            </material>
        </visual>
    </link>
    <joint name="lidar_joint" type="fixed">
        <parent>base_link</parent>
        <child>lidar_link</child>
    </joint>
    <link name="lidar_link">
        <pose>9.07392 0.361634 17.7084 0 0 0</pose>
        <visual name="visual">
            <geometry><mesh><uri>file:///home/danil/Documents/ROSWorkspaces/RosMiniProject/src/making_delivery/models/lidar.obj</uri></mesh></geometry>
            <material>
                <ambient>1 1 1 1</ambient>
                <diffuse>1 1 1 1</diffuse>
                <pbr><metal>
                    <albedo_map>resources://T_Lidar_BC_4K.png</albedo_map>
                    <roughness>1</roughness>
                    <metalness>0</metalness>
                </metal></pbr>
            </material>
        </visual>
        <collision name="collision">
            <pose>0 0 1.5 0 0 0</pose>
            <geometry><box><size>3.5 3.5 2.36</size></box></geometry>
        </collision>
         <sensor name="gpu_lidar" type="gpu_lidar">
                <topic>lidar</topic>
                <update_rate>10</update_rate>
                <ray>
                    <scan>
                        <horizontal>
                            <samples>640</samples>
                            <resolution>1</resolution>
                            <min_angle>0</min_angle>
                            <max_angle>0.5</max_angle>
                        </horizontal>
                        <vertical>
                            <samples>640</samples>
                            <resolution>1</resolution>
                            <min_angle>0</min_angle>
                            <max_angle>0.5</max_angle>
                        </vertical>
                    </scan>
                    <range>
                        <min>0.08</min>
                        <max>10</max>
                        <resolution>0.01</resolution>
                    </range>
                </ray>
                <always_on>1</always_on>
                <visualize>true</visualize>
            </sensor>
    </link>


    <link name="left_front_wheel_link">
        <pose>10 10 5 1.57 0 0</pose>
        <visual name="visual">
            <pose>0 0 -1.1 0 0 0</pose>
            <geometry><box><size>5 5 5</size></box></geometry>
        </visual>
        <collision name="collision">
            <pose>0 0 -1.1 0 0 0</pose>
            <geometry><cylinder><radius>2.5</radius><length>2</length></cylinder></geometry>
        </collision>
        <inertial>
          <mass>50.0</mass>
          <inertia>
            <ixx>0.1</ixx>
            <iyy>0.1</iyy>
            <izz>0.1</izz>
          </inertia>
        </inertial>
    </link>
    <joint name="left_front_wheel_joint" type="revolute">
        <parent>base_link</parent>
        <child>left_front_wheel_link</child>
        <axis><xyz>0 0 1</xyz></axis>
    </joint>

    <link name="left_middle_wheel_link">
        <pose>0 10 5 1.57 0 0</pose>
        <visual name="visual">
            <pose>0 0 -1.1 0 0 0</pose>
            <geometry><cylinder><radius>2.5</radius><length>2</length></cylinder></geometry>
        </visual>
        <collision name="collision">
            <pose>0 0 -1.1 0 0 0</pose>
            <geometry><cylinder><radius>2.5</radius><length>2</length></cylinder></geometry>
        </collision>
    </link>
    <joint name="left_middle_wheel_joint" type="fixed">
        <parent>base_link</parent>
        <child>left_middle_wheel_link</child>
    </joint>

    <link name="left_back_wheel_link">
        <pose>-10 10 5 1.57 0 0</pose>
        <visual name="visual">
            <pose>0 0 -1.1 0 0 0</pose>
            <geometry><cylinder><radius>2.5</radius><length>2</length></cylinder></geometry>
        </visual>
        <collision name="collision">
            <pose>0 0 -1.1 0 0 0</pose>
            <geometry><cylinder><radius>2.5</radius><length>2</length></cylinder></geometry>
        </collision>
    </link>
    <joint name="left_back_wheel_joint" type="fixed">
        <parent>base_link</parent>
        <child>left_back_wheel_link</child>
    </joint>

    <link name="right_front_wheel_link">
        <pose>10 -10 5 1.57 0 0</pose>
        <visual name="visual">
            <pose>0 0 1.1 0 0 0</pose>
            <geometry><cylinder><radius>2.5</radius><length>2</length></cylinder></geometry>
        </visual>
        <collision name="collision">
            <pose>0 0 1.1 0 0 0</pose>
            <geometry><cylinder><radius>2.5</radius><length>2</length></cylinder></geometry>
        </collision>
    </link>
    <joint name="right_front_wheel_joint" type="fixed">
        <parent>base_link</parent>
        <child>right_front_wheel_link</child>
    </joint>

    <link name="right_middle_wheel_link">
        <pose>0 -10 5 1.57 0 0</pose>
        <visual name="visual">
            <pose>0 0 1.1 0 0 0</pose>
            <geometry><cylinder><radius>2.5</radius><length>2</length></cylinder></geometry>
        </visual>
        <collision name="collision">
            <pose>0 0 1.1 0 0 0</pose>
            <geometry><cylinder><radius>2.5</radius><length>2</length></cylinder></geometry>
        </collision>
    </link>
    <joint name="right_middle_wheel_joint" type="fixed">
        <parent>base_link</parent>
        <child>right_middle_wheel_link</child>
    </joint>

    <link name="right_back_wheel_link">
        <pose>-10 -10 5 1.57 0 0</pose>
        <visual name="visual">
            <pose>0 0 1.1 0 0 0</pose>
            <geometry><cylinder><radius>2.5</radius><length>2</length></cylinder></geometry>
        </visual>
        <collision name="collision">
            <pose>0 0 1.1 0 0 0</pose>
            <geometry><cylinder><radius>2.5</radius><length>2</length></cylinder></geometry>
        </collision>
    </link>
    <joint name="right_back_wheel_joint" type="fixed">
        <parent>base_link</parent>
        <child>right_back_wheel_link</child>
    </joint>
</model>
</sdf>
